An error occurred: HTTPSConnectionPool(host='your-api-endpoint-here.com', port=443): Max retries exceeded with url: /data (Caused by ConnectTimeoutError(<urllib3.connection.HTTPSConnection object at 0x000001E9AF0D74D0>, 'Connection to your-api-endpoint-here.com timed out. (connect timeout=None)'))
Traceback: Traceback (most recent call last):
  File "C:\Users\Andi\AppData\Local\Programs\Python\Python312\Lib\site-packages\urllib3\connection.py", line 203, in _new_conn
    sock = connection.create_connection(
           ^^^^^^^^^^^^^^^^^^^^^^^^^^^^^
  File "C:\Users\Andi\AppData\Local\Programs\Python\Python312\Lib\site-packages\urllib3\util\connection.py", line 85, in create_connection
    raise err
  File "C:\Users\Andi\AppData\Local\Programs\Python\Python312\Lib\site-packages\urllib3\util\connection.py", line 73, in create_connection
    sock.connect(sa)
TimeoutError: [WinError 10060] A connection attempt failed because the connected party did not properly respond after a period of time, or established connection failed because connected host has failed to respond

The above exception was the direct cause of the following exception:

Traceback (most recent call last):
  File "C:\Users\Andi\AppData\Local\Programs\Python\Python312\Lib\site-packages\urllib3\connectionpool.py", line 790, in urlopen
    response = self._make_request(
               ^^^^^^^^^^^^^^^^^^^
  File "C:\Users\Andi\AppData\Local\Programs\Python\Python312\Lib\site-packages\urllib3\connectionpool.py", line 491, in _make_request
    raise new_e
  File "C:\Users\Andi\AppData\Local\Programs\Python\Python312\Lib\site-packages\urllib3\connectionpool.py", line 467, in _make_request
    self._validate_conn(conn)
  File "C:\Users\Andi\AppData\Local\Programs\Python\Python312\Lib\site-packages\urllib3\connectionpool.py", line 1096, in _validate_conn
    conn.connect()
  File "C:\Users\Andi\AppData\Local\Programs\Python\Python312\Lib\site-packages\urllib3\connection.py", line 611, in connect
    self.sock = sock = self._new_conn()
                       ^^^^^^^^^^^^^^^^
  File "C:\Users\Andi\AppData\Local\Programs\Python\Python312\Lib\site-packages\urllib3\connection.py", line 212, in _new_conn
    raise ConnectTimeoutError(
urllib3.exceptions.ConnectTimeoutError: (<urllib3.connection.HTTPSConnection object at 0x000001E9AF0D74D0>, 'Connection to your-api-endpoint-here.com timed out. (connect timeout=None)')

The above exception was the direct cause of the following exception:

Traceback (most recent call last):
  File "C:\Users\Andi\AppData\Local\Programs\Python\Python312\Lib\site-packages\requests\adapters.py", line 486, in send
    resp = conn.urlopen(
           ^^^^^^^^^^^^^
  File "C:\Users\Andi\AppData\Local\Programs\Python\Python312\Lib\site-packages\urllib3\connectionpool.py", line 844, in urlopen
    retries = retries.increment(
              ^^^^^^^^^^^^^^^^^^
  File "C:\Users\Andi\AppData\Local\Programs\Python\Python312\Lib\site-packages\urllib3\util\retry.py", line 515, in increment
    raise MaxRetryError(_pool, url, reason) from reason  # type: ignore[arg-type]
    ^^^^^^^^^^^^^^^^^^^^^^^^^^^^^^^^^^^^^^^^^^^^^^^^^^^
urllib3.exceptions.MaxRetryError: HTTPSConnectionPool(host='your-api-endpoint-here.com', port=443): Max retries exceeded with url: /data (Caused by ConnectTimeoutError(<urllib3.connection.HTTPSConnection object at 0x000001E9AF0D74D0>, 'Connection to your-api-endpoint-here.com timed out. (connect timeout=None)'))

During handling of the above exception, another exception occurred:

Traceback (most recent call last):
  File "C:\acm-client\main.py", line 36, in <module>
    response = requests.post(api_endpoint, json=payload)
               ^^^^^^^^^^^^^^^^^^^^^^^^^^^^^^^^^^^^^^^^^
  File "C:\Users\Andi\AppData\Local\Programs\Python\Python312\Lib\site-packages\requests\api.py", line 115, in post
    return request("post", url, data=data, json=json, **kwargs)
           ^^^^^^^^^^^^^^^^^^^^^^^^^^^^^^^^^^^^^^^^^^^^^^^^^^^^
  File "C:\Users\Andi\AppData\Local\Programs\Python\Python312\Lib\site-packages\requests\api.py", line 59, in request
    return session.request(method=method, url=url, **kwargs)
           ^^^^^^^^^^^^^^^^^^^^^^^^^^^^^^^^^^^^^^^^^^^^^^^^^
  File "C:\Users\Andi\AppData\Local\Programs\Python\Python312\Lib\site-packages\requests\sessions.py", line 589, in request
    resp = self.send(prep, **send_kwargs)
           ^^^^^^^^^^^^^^^^^^^^^^^^^^^^^^
  File "C:\Users\Andi\AppData\Local\Programs\Python\Python312\Lib\site-packages\requests\sessions.py", line 703, in send
    r = adapter.send(request, **kwargs)
        ^^^^^^^^^^^^^^^^^^^^^^^^^^^^^^^
  File "C:\Users\Andi\AppData\Local\Programs\Python\Python312\Lib\site-packages\requests\adapters.py", line 507, in send
    raise ConnectTimeout(e, request=request)
requests.exceptions.ConnectTimeout: HTTPSConnectionPool(host='your-api-endpoint-here.com', port=443): Max retries exceeded with url: /data (Caused by ConnectTimeoutError(<urllib3.connection.HTTPSConnection object at 0x000001E9AF0D74D0>, 'Connection to your-api-endpoint-here.com timed out. (connect timeout=None)'))

An error occurred: HTTPSConnectionPool(host='your-api-endpoint-here.com', port=443): Max retries exceeded with url: /data (Caused by ConnectTimeoutError(<urllib3.connection.HTTPSConnection object at 0x00000294DD9A76B0>, 'Connection to your-api-endpoint-here.com timed out. (connect timeout=None)'))
Traceback: Traceback (most recent call last):
  File "C:\Users\Andi\AppData\Local\Programs\Python\Python312\Lib\site-packages\urllib3\connection.py", line 203, in _new_conn
    sock = connection.create_connection(
           ^^^^^^^^^^^^^^^^^^^^^^^^^^^^^
  File "C:\Users\Andi\AppData\Local\Programs\Python\Python312\Lib\site-packages\urllib3\util\connection.py", line 85, in create_connection
    raise err
  File "C:\Users\Andi\AppData\Local\Programs\Python\Python312\Lib\site-packages\urllib3\util\connection.py", line 73, in create_connection
    sock.connect(sa)
TimeoutError: [WinError 10060] A connection attempt failed because the connected party did not properly respond after a period of time, or established connection failed because connected host has failed to respond

The above exception was the direct cause of the following exception:

Traceback (most recent call last):
  File "C:\Users\Andi\AppData\Local\Programs\Python\Python312\Lib\site-packages\urllib3\connectionpool.py", line 790, in urlopen
    response = self._make_request(
               ^^^^^^^^^^^^^^^^^^^
  File "C:\Users\Andi\AppData\Local\Programs\Python\Python312\Lib\site-packages\urllib3\connectionpool.py", line 491, in _make_request
    raise new_e
  File "C:\Users\Andi\AppData\Local\Programs\Python\Python312\Lib\site-packages\urllib3\connectionpool.py", line 467, in _make_request
    self._validate_conn(conn)
  File "C:\Users\Andi\AppData\Local\Programs\Python\Python312\Lib\site-packages\urllib3\connectionpool.py", line 1096, in _validate_conn
    conn.connect()
  File "C:\Users\Andi\AppData\Local\Programs\Python\Python312\Lib\site-packages\urllib3\connection.py", line 611, in connect
    self.sock = sock = self._new_conn()
                       ^^^^^^^^^^^^^^^^
  File "C:\Users\Andi\AppData\Local\Programs\Python\Python312\Lib\site-packages\urllib3\connection.py", line 212, in _new_conn
    raise ConnectTimeoutError(
urllib3.exceptions.ConnectTimeoutError: (<urllib3.connection.HTTPSConnection object at 0x00000294DD9A76B0>, 'Connection to your-api-endpoint-here.com timed out. (connect timeout=None)')

The above exception was the direct cause of the following exception:

Traceback (most recent call last):
  File "C:\Users\Andi\AppData\Local\Programs\Python\Python312\Lib\site-packages\requests\adapters.py", line 486, in send
    resp = conn.urlopen(
           ^^^^^^^^^^^^^
  File "C:\Users\Andi\AppData\Local\Programs\Python\Python312\Lib\site-packages\urllib3\connectionpool.py", line 844, in urlopen
    retries = retries.increment(
              ^^^^^^^^^^^^^^^^^^
  File "C:\Users\Andi\AppData\Local\Programs\Python\Python312\Lib\site-packages\urllib3\util\retry.py", line 515, in increment
    raise MaxRetryError(_pool, url, reason) from reason  # type: ignore[arg-type]
    ^^^^^^^^^^^^^^^^^^^^^^^^^^^^^^^^^^^^^^^^^^^^^^^^^^^
urllib3.exceptions.MaxRetryError: HTTPSConnectionPool(host='your-api-endpoint-here.com', port=443): Max retries exceeded with url: /data (Caused by ConnectTimeoutError(<urllib3.connection.HTTPSConnection object at 0x00000294DD9A76B0>, 'Connection to your-api-endpoint-here.com timed out. (connect timeout=None)'))

During handling of the above exception, another exception occurred:

Traceback (most recent call last):
  File "C:\acm-client\main.py", line 36, in <module>
    response = requests.post(api_endpoint, json=payload)
               ^^^^^^^^^^^^^^^^^^^^^^^^^^^^^^^^^^^^^^^^^
  File "C:\Users\Andi\AppData\Local\Programs\Python\Python312\Lib\site-packages\requests\api.py", line 115, in post
    return request("post", url, data=data, json=json, **kwargs)
           ^^^^^^^^^^^^^^^^^^^^^^^^^^^^^^^^^^^^^^^^^^^^^^^^^^^^
  File "C:\Users\Andi\AppData\Local\Programs\Python\Python312\Lib\site-packages\requests\api.py", line 59, in request
    return session.request(method=method, url=url, **kwargs)
           ^^^^^^^^^^^^^^^^^^^^^^^^^^^^^^^^^^^^^^^^^^^^^^^^^
  File "C:\Users\Andi\AppData\Local\Programs\Python\Python312\Lib\site-packages\requests\sessions.py", line 589, in request
    resp = self.send(prep, **send_kwargs)
           ^^^^^^^^^^^^^^^^^^^^^^^^^^^^^^
  File "C:\Users\Andi\AppData\Local\Programs\Python\Python312\Lib\site-packages\requests\sessions.py", line 703, in send
    r = adapter.send(request, **kwargs)
        ^^^^^^^^^^^^^^^^^^^^^^^^^^^^^^^
  File "C:\Users\Andi\AppData\Local\Programs\Python\Python312\Lib\site-packages\requests\adapters.py", line 507, in send
    raise ConnectTimeout(e, request=request)
requests.exceptions.ConnectTimeout: HTTPSConnectionPool(host='your-api-endpoint-here.com', port=443): Max retries exceeded with url: /data (Caused by ConnectTimeoutError(<urllib3.connection.HTTPSConnection object at 0x00000294DD9A76B0>, 'Connection to your-api-endpoint-here.com timed out. (connect timeout=None)'))

An error occurred: HTTPSConnectionPool(host='your-api-endpoint-here.com', port=443): Max retries exceeded with url: /data (Caused by ConnectTimeoutError(<urllib3.connection.HTTPSConnection object at 0x000002578424BC20>, 'Connection to your-api-endpoint-here.com timed out. (connect timeout=None)'))
Traceback: Traceback (most recent call last):
  File "C:\Users\Andi\AppData\Local\Programs\Python\Python312\Lib\site-packages\urllib3\connection.py", line 203, in _new_conn
    sock = connection.create_connection(
           ^^^^^^^^^^^^^^^^^^^^^^^^^^^^^
  File "C:\Users\Andi\AppData\Local\Programs\Python\Python312\Lib\site-packages\urllib3\util\connection.py", line 85, in create_connection
    raise err
  File "C:\Users\Andi\AppData\Local\Programs\Python\Python312\Lib\site-packages\urllib3\util\connection.py", line 73, in create_connection
    sock.connect(sa)
TimeoutError: [WinError 10060] A connection attempt failed because the connected party did not properly respond after a period of time, or established connection failed because connected host has failed to respond

The above exception was the direct cause of the following exception:

Traceback (most recent call last):
  File "C:\Users\Andi\AppData\Local\Programs\Python\Python312\Lib\site-packages\urllib3\connectionpool.py", line 790, in urlopen
    response = self._make_request(
               ^^^^^^^^^^^^^^^^^^^
  File "C:\Users\Andi\AppData\Local\Programs\Python\Python312\Lib\site-packages\urllib3\connectionpool.py", line 491, in _make_request
    raise new_e
  File "C:\Users\Andi\AppData\Local\Programs\Python\Python312\Lib\site-packages\urllib3\connectionpool.py", line 467, in _make_request
    self._validate_conn(conn)
  File "C:\Users\Andi\AppData\Local\Programs\Python\Python312\Lib\site-packages\urllib3\connectionpool.py", line 1096, in _validate_conn
    conn.connect()
  File "C:\Users\Andi\AppData\Local\Programs\Python\Python312\Lib\site-packages\urllib3\connection.py", line 611, in connect
    self.sock = sock = self._new_conn()
                       ^^^^^^^^^^^^^^^^
  File "C:\Users\Andi\AppData\Local\Programs\Python\Python312\Lib\site-packages\urllib3\connection.py", line 212, in _new_conn
    raise ConnectTimeoutError(
urllib3.exceptions.ConnectTimeoutError: (<urllib3.connection.HTTPSConnection object at 0x000002578424BC20>, 'Connection to your-api-endpoint-here.com timed out. (connect timeout=None)')

The above exception was the direct cause of the following exception:

Traceback (most recent call last):
  File "C:\Users\Andi\AppData\Local\Programs\Python\Python312\Lib\site-packages\requests\adapters.py", line 486, in send
    resp = conn.urlopen(
           ^^^^^^^^^^^^^
  File "C:\Users\Andi\AppData\Local\Programs\Python\Python312\Lib\site-packages\urllib3\connectionpool.py", line 844, in urlopen
    retries = retries.increment(
              ^^^^^^^^^^^^^^^^^^
  File "C:\Users\Andi\AppData\Local\Programs\Python\Python312\Lib\site-packages\urllib3\util\retry.py", line 515, in increment
    raise MaxRetryError(_pool, url, reason) from reason  # type: ignore[arg-type]
    ^^^^^^^^^^^^^^^^^^^^^^^^^^^^^^^^^^^^^^^^^^^^^^^^^^^
urllib3.exceptions.MaxRetryError: HTTPSConnectionPool(host='your-api-endpoint-here.com', port=443): Max retries exceeded with url: /data (Caused by ConnectTimeoutError(<urllib3.connection.HTTPSConnection object at 0x000002578424BC20>, 'Connection to your-api-endpoint-here.com timed out. (connect timeout=None)'))

During handling of the above exception, another exception occurred:

Traceback (most recent call last):
  File "C:\acm-client\main.py", line 36, in <module>
    response = requests.post(api_endpoint, json=payload)
               ^^^^^^^^^^^^^^^^^^^^^^^^^^^^^^^^^^^^^^^^^
  File "C:\Users\Andi\AppData\Local\Programs\Python\Python312\Lib\site-packages\requests\api.py", line 115, in post
    return request("post", url, data=data, json=json, **kwargs)
           ^^^^^^^^^^^^^^^^^^^^^^^^^^^^^^^^^^^^^^^^^^^^^^^^^^^^
  File "C:\Users\Andi\AppData\Local\Programs\Python\Python312\Lib\site-packages\requests\api.py", line 59, in request
    return session.request(method=method, url=url, **kwargs)
           ^^^^^^^^^^^^^^^^^^^^^^^^^^^^^^^^^^^^^^^^^^^^^^^^^
  File "C:\Users\Andi\AppData\Local\Programs\Python\Python312\Lib\site-packages\requests\sessions.py", line 589, in request
    resp = self.send(prep, **send_kwargs)
           ^^^^^^^^^^^^^^^^^^^^^^^^^^^^^^
  File "C:\Users\Andi\AppData\Local\Programs\Python\Python312\Lib\site-packages\requests\sessions.py", line 703, in send
    r = adapter.send(request, **kwargs)
        ^^^^^^^^^^^^^^^^^^^^^^^^^^^^^^^
  File "C:\Users\Andi\AppData\Local\Programs\Python\Python312\Lib\site-packages\requests\adapters.py", line 507, in send
    raise ConnectTimeout(e, request=request)
requests.exceptions.ConnectTimeout: HTTPSConnectionPool(host='your-api-endpoint-here.com', port=443): Max retries exceeded with url: /data (Caused by ConnectTimeoutError(<urllib3.connection.HTTPSConnection object at 0x000002578424BC20>, 'Connection to your-api-endpoint-here.com timed out. (connect timeout=None)'))

An error occurred: HTTPSConnectionPool(host='your-api-endpoint-here.com', port=443): Max retries exceeded with url: /data (Caused by ConnectTimeoutError(<urllib3.connection.HTTPSConnection object at 0x000002F8E2FF7560>, 'Connection to your-api-endpoint-here.com timed out. (connect timeout=None)'))
Traceback: Traceback (most recent call last):
  File "C:\Users\Andi\AppData\Local\Programs\Python\Python312\Lib\site-packages\urllib3\connection.py", line 203, in _new_conn
    sock = connection.create_connection(
           ^^^^^^^^^^^^^^^^^^^^^^^^^^^^^
  File "C:\Users\Andi\AppData\Local\Programs\Python\Python312\Lib\site-packages\urllib3\util\connection.py", line 85, in create_connection
    raise err
  File "C:\Users\Andi\AppData\Local\Programs\Python\Python312\Lib\site-packages\urllib3\util\connection.py", line 73, in create_connection
    sock.connect(sa)
TimeoutError: [WinError 10060] A connection attempt failed because the connected party did not properly respond after a period of time, or established connection failed because connected host has failed to respond

The above exception was the direct cause of the following exception:

Traceback (most recent call last):
  File "C:\Users\Andi\AppData\Local\Programs\Python\Python312\Lib\site-packages\urllib3\connectionpool.py", line 790, in urlopen
    response = self._make_request(
               ^^^^^^^^^^^^^^^^^^^
  File "C:\Users\Andi\AppData\Local\Programs\Python\Python312\Lib\site-packages\urllib3\connectionpool.py", line 491, in _make_request
    raise new_e
  File "C:\Users\Andi\AppData\Local\Programs\Python\Python312\Lib\site-packages\urllib3\connectionpool.py", line 467, in _make_request
    self._validate_conn(conn)
  File "C:\Users\Andi\AppData\Local\Programs\Python\Python312\Lib\site-packages\urllib3\connectionpool.py", line 1096, in _validate_conn
    conn.connect()
  File "C:\Users\Andi\AppData\Local\Programs\Python\Python312\Lib\site-packages\urllib3\connection.py", line 611, in connect
    self.sock = sock = self._new_conn()
                       ^^^^^^^^^^^^^^^^
  File "C:\Users\Andi\AppData\Local\Programs\Python\Python312\Lib\site-packages\urllib3\connection.py", line 212, in _new_conn
    raise ConnectTimeoutError(
urllib3.exceptions.ConnectTimeoutError: (<urllib3.connection.HTTPSConnection object at 0x000002F8E2FF7560>, 'Connection to your-api-endpoint-here.com timed out. (connect timeout=None)')

The above exception was the direct cause of the following exception:

Traceback (most recent call last):
  File "C:\Users\Andi\AppData\Local\Programs\Python\Python312\Lib\site-packages\requests\adapters.py", line 486, in send
    resp = conn.urlopen(
           ^^^^^^^^^^^^^
  File "C:\Users\Andi\AppData\Local\Programs\Python\Python312\Lib\site-packages\urllib3\connectionpool.py", line 844, in urlopen
    retries = retries.increment(
              ^^^^^^^^^^^^^^^^^^
  File "C:\Users\Andi\AppData\Local\Programs\Python\Python312\Lib\site-packages\urllib3\util\retry.py", line 515, in increment
    raise MaxRetryError(_pool, url, reason) from reason  # type: ignore[arg-type]
    ^^^^^^^^^^^^^^^^^^^^^^^^^^^^^^^^^^^^^^^^^^^^^^^^^^^
urllib3.exceptions.MaxRetryError: HTTPSConnectionPool(host='your-api-endpoint-here.com', port=443): Max retries exceeded with url: /data (Caused by ConnectTimeoutError(<urllib3.connection.HTTPSConnection object at 0x000002F8E2FF7560>, 'Connection to your-api-endpoint-here.com timed out. (connect timeout=None)'))

During handling of the above exception, another exception occurred:

Traceback (most recent call last):
  File "C:\acm-client\main.py", line 36, in <module>
    response = requests.post(api_endpoint, json=payload)
               ^^^^^^^^^^^^^^^^^^^^^^^^^^^^^^^^^^^^^^^^^
  File "C:\Users\Andi\AppData\Local\Programs\Python\Python312\Lib\site-packages\requests\api.py", line 115, in post
    return request("post", url, data=data, json=json, **kwargs)
           ^^^^^^^^^^^^^^^^^^^^^^^^^^^^^^^^^^^^^^^^^^^^^^^^^^^^
  File "C:\Users\Andi\AppData\Local\Programs\Python\Python312\Lib\site-packages\requests\api.py", line 59, in request
    return session.request(method=method, url=url, **kwargs)
           ^^^^^^^^^^^^^^^^^^^^^^^^^^^^^^^^^^^^^^^^^^^^^^^^^
  File "C:\Users\Andi\AppData\Local\Programs\Python\Python312\Lib\site-packages\requests\sessions.py", line 589, in request
    resp = self.send(prep, **send_kwargs)
           ^^^^^^^^^^^^^^^^^^^^^^^^^^^^^^
  File "C:\Users\Andi\AppData\Local\Programs\Python\Python312\Lib\site-packages\requests\sessions.py", line 703, in send
    r = adapter.send(request, **kwargs)
        ^^^^^^^^^^^^^^^^^^^^^^^^^^^^^^^
  File "C:\Users\Andi\AppData\Local\Programs\Python\Python312\Lib\site-packages\requests\adapters.py", line 507, in send
    raise ConnectTimeout(e, request=request)
requests.exceptions.ConnectTimeout: HTTPSConnectionPool(host='your-api-endpoint-here.com', port=443): Max retries exceeded with url: /data (Caused by ConnectTimeoutError(<urllib3.connection.HTTPSConnection object at 0x000002F8E2FF7560>, 'Connection to your-api-endpoint-here.com timed out. (connect timeout=None)'))

An error occurred: HTTPSConnectionPool(host='your-api-endpoint-here.com', port=443): Max retries exceeded with url: /data (Caused by ConnectTimeoutError(<urllib3.connection.HTTPSConnection object at 0x0000028777B470B0>, 'Connection to your-api-endpoint-here.com timed out. (connect timeout=None)'))
An error occurred: HTTPSConnectionPool(host='your-api-endpoint-here.com', port=443): Max retries exceeded with url: /data (Caused by ConnectTimeoutError(<urllib3.connection.HTTPSConnection object at 0x000001E0943ED940>, 'Connection to your-api-endpoint-here.com timed out. (connect timeout=None)'))
Traceback: Traceback (most recent call last):
  File "C:\Users\Andi\AppData\Local\Programs\Python\Python312\Lib\site-packages\urllib3\connection.py", line 203, in _new_conn
    sock = connection.create_connection(
           ^^^^^^^^^^^^^^^^^^^^^^^^^^^^^
  File "C:\Users\Andi\AppData\Local\Programs\Python\Python312\Lib\site-packages\urllib3\util\connection.py", line 85, in create_connection
    raise err
  File "C:\Users\Andi\AppData\Local\Programs\Python\Python312\Lib\site-packages\urllib3\util\connection.py", line 73, in create_connection
    sock.connect(sa)
TimeoutError: [WinError 10060] A connection attempt failed because the connected party did not properly respond after a period of time, or established connection failed because connected host has failed to respond

The above exception was the direct cause of the following exception:

Traceback (most recent call last):
  File "C:\Users\Andi\AppData\Local\Programs\Python\Python312\Lib\site-packages\urllib3\connectionpool.py", line 790, in urlopen
    response = self._make_request(
               ^^^^^^^^^^^^^^^^^^^
  File "C:\Users\Andi\AppData\Local\Programs\Python\Python312\Lib\site-packages\urllib3\connectionpool.py", line 491, in _make_request
    raise new_e
  File "C:\Users\Andi\AppData\Local\Programs\Python\Python312\Lib\site-packages\urllib3\connectionpool.py", line 467, in _make_request
    self._validate_conn(conn)
  File "C:\Users\Andi\AppData\Local\Programs\Python\Python312\Lib\site-packages\urllib3\connectionpool.py", line 1096, in _validate_conn
    conn.connect()
  File "C:\Users\Andi\AppData\Local\Programs\Python\Python312\Lib\site-packages\urllib3\connection.py", line 611, in connect
    self.sock = sock = self._new_conn()
                       ^^^^^^^^^^^^^^^^
  File "C:\Users\Andi\AppData\Local\Programs\Python\Python312\Lib\site-packages\urllib3\connection.py", line 212, in _new_conn
    raise ConnectTimeoutError(
urllib3.exceptions.ConnectTimeoutError: (<urllib3.connection.HTTPSConnection object at 0x000001E0943ED940>, 'Connection to your-api-endpoint-here.com timed out. (connect timeout=None)')

The above exception was the direct cause of the following exception:

Traceback (most recent call last):
  File "C:\Users\Andi\AppData\Local\Programs\Python\Python312\Lib\site-packages\requests\adapters.py", line 486, in send
    resp = conn.urlopen(
           ^^^^^^^^^^^^^
  File "C:\Users\Andi\AppData\Local\Programs\Python\Python312\Lib\site-packages\urllib3\connectionpool.py", line 844, in urlopen
    retries = retries.increment(
              ^^^^^^^^^^^^^^^^^^
  File "C:\Users\Andi\AppData\Local\Programs\Python\Python312\Lib\site-packages\urllib3\util\retry.py", line 515, in increment
    raise MaxRetryError(_pool, url, reason) from reason  # type: ignore[arg-type]
    ^^^^^^^^^^^^^^^^^^^^^^^^^^^^^^^^^^^^^^^^^^^^^^^^^^^
urllib3.exceptions.MaxRetryError: HTTPSConnectionPool(host='your-api-endpoint-here.com', port=443): Max retries exceeded with url: /data (Caused by ConnectTimeoutError(<urllib3.connection.HTTPSConnection object at 0x000001E0943ED940>, 'Connection to your-api-endpoint-here.com timed out. (connect timeout=None)'))

During handling of the above exception, another exception occurred:

Traceback (most recent call last):
  File "C:\acm-client\main.py", line 36, in <module>
    response = requests.post(api_endpoint, json=payload)
               ^^^^^^^^^^^^^^^^^^^^^^^^^^^^^^^^^^^^^^^^^
  File "C:\Users\Andi\AppData\Local\Programs\Python\Python312\Lib\site-packages\requests\api.py", line 115, in post
    return request("post", url, data=data, json=json, **kwargs)
           ^^^^^^^^^^^^^^^^^^^^^^^^^^^^^^^^^^^^^^^^^^^^^^^^^^^^
  File "C:\Users\Andi\AppData\Local\Programs\Python\Python312\Lib\site-packages\requests\api.py", line 59, in request
    return session.request(method=method, url=url, **kwargs)
           ^^^^^^^^^^^^^^^^^^^^^^^^^^^^^^^^^^^^^^^^^^^^^^^^^
  File "C:\Users\Andi\AppData\Local\Programs\Python\Python312\Lib\site-packages\requests\sessions.py", line 589, in request
    resp = self.send(prep, **send_kwargs)
           ^^^^^^^^^^^^^^^^^^^^^^^^^^^^^^
  File "C:\Users\Andi\AppData\Local\Programs\Python\Python312\Lib\site-packages\requests\sessions.py", line 703, in send
    r = adapter.send(request, **kwargs)
        ^^^^^^^^^^^^^^^^^^^^^^^^^^^^^^^
  File "C:\Users\Andi\AppData\Local\Programs\Python\Python312\Lib\site-packages\requests\adapters.py", line 507, in send
    raise ConnectTimeout(e, request=request)
requests.exceptions.ConnectTimeout: HTTPSConnectionPool(host='your-api-endpoint-here.com', port=443): Max retries exceeded with url: /data (Caused by ConnectTimeoutError(<urllib3.connection.HTTPSConnection object at 0x000001E0943ED940>, 'Connection to your-api-endpoint-here.com timed out. (connect timeout=None)'))

An error occurred: HTTPSConnectionPool(host='your-api-endpoint-here.com', port=443): Max retries exceeded with url: /data (Caused by ConnectTimeoutError(<urllib3.connection.HTTPSConnection object at 0x000001BDF6B9B6E0>, 'Connection to your-api-endpoint-here.com timed out. (connect timeout=None)'))
Traceback: Traceback (most recent call last):
  File "C:\Users\Andi\AppData\Local\Programs\Python\Python312\Lib\site-packages\urllib3\connection.py", line 203, in _new_conn
    sock = connection.create_connection(
           ^^^^^^^^^^^^^^^^^^^^^^^^^^^^^
  File "C:\Users\Andi\AppData\Local\Programs\Python\Python312\Lib\site-packages\urllib3\util\connection.py", line 85, in create_connection
    raise err
  File "C:\Users\Andi\AppData\Local\Programs\Python\Python312\Lib\site-packages\urllib3\util\connection.py", line 73, in create_connection
    sock.connect(sa)
TimeoutError: [WinError 10060] A connection attempt failed because the connected party did not properly respond after a period of time, or established connection failed because connected host has failed to respond

The above exception was the direct cause of the following exception:

Traceback (most recent call last):
  File "C:\Users\Andi\AppData\Local\Programs\Python\Python312\Lib\site-packages\urllib3\connectionpool.py", line 790, in urlopen
    response = self._make_request(
               ^^^^^^^^^^^^^^^^^^^
  File "C:\Users\Andi\AppData\Local\Programs\Python\Python312\Lib\site-packages\urllib3\connectionpool.py", line 491, in _make_request
    raise new_e
  File "C:\Users\Andi\AppData\Local\Programs\Python\Python312\Lib\site-packages\urllib3\connectionpool.py", line 467, in _make_request
    self._validate_conn(conn)
  File "C:\Users\Andi\AppData\Local\Programs\Python\Python312\Lib\site-packages\urllib3\connectionpool.py", line 1096, in _validate_conn
    conn.connect()
  File "C:\Users\Andi\AppData\Local\Programs\Python\Python312\Lib\site-packages\urllib3\connection.py", line 611, in connect
    self.sock = sock = self._new_conn()
                       ^^^^^^^^^^^^^^^^
  File "C:\Users\Andi\AppData\Local\Programs\Python\Python312\Lib\site-packages\urllib3\connection.py", line 212, in _new_conn
    raise ConnectTimeoutError(
urllib3.exceptions.ConnectTimeoutError: (<urllib3.connection.HTTPSConnection object at 0x000001BDF6B9B6E0>, 'Connection to your-api-endpoint-here.com timed out. (connect timeout=None)')

The above exception was the direct cause of the following exception:

Traceback (most recent call last):
  File "C:\Users\Andi\AppData\Local\Programs\Python\Python312\Lib\site-packages\requests\adapters.py", line 486, in send
    resp = conn.urlopen(
           ^^^^^^^^^^^^^
  File "C:\Users\Andi\AppData\Local\Programs\Python\Python312\Lib\site-packages\urllib3\connectionpool.py", line 844, in urlopen
    retries = retries.increment(
              ^^^^^^^^^^^^^^^^^^
  File "C:\Users\Andi\AppData\Local\Programs\Python\Python312\Lib\site-packages\urllib3\util\retry.py", line 515, in increment
    raise MaxRetryError(_pool, url, reason) from reason  # type: ignore[arg-type]
    ^^^^^^^^^^^^^^^^^^^^^^^^^^^^^^^^^^^^^^^^^^^^^^^^^^^
urllib3.exceptions.MaxRetryError: HTTPSConnectionPool(host='your-api-endpoint-here.com', port=443): Max retries exceeded with url: /data (Caused by ConnectTimeoutError(<urllib3.connection.HTTPSConnection object at 0x000001BDF6B9B6E0>, 'Connection to your-api-endpoint-here.com timed out. (connect timeout=None)'))

During handling of the above exception, another exception occurred:

Traceback (most recent call last):
  File "C:\acm-client\main.py", line 36, in <module>
    response = requests.post(api_endpoint, json=payload)
               ^^^^^^^^^^^^^^^^^^^^^^^^^^^^^^^^^^^^^^^^^
  File "C:\Users\Andi\AppData\Local\Programs\Python\Python312\Lib\site-packages\requests\api.py", line 115, in post
    return request("post", url, data=data, json=json, **kwargs)
           ^^^^^^^^^^^^^^^^^^^^^^^^^^^^^^^^^^^^^^^^^^^^^^^^^^^^
  File "C:\Users\Andi\AppData\Local\Programs\Python\Python312\Lib\site-packages\requests\api.py", line 59, in request
    return session.request(method=method, url=url, **kwargs)
           ^^^^^^^^^^^^^^^^^^^^^^^^^^^^^^^^^^^^^^^^^^^^^^^^^
  File "C:\Users\Andi\AppData\Local\Programs\Python\Python312\Lib\site-packages\requests\sessions.py", line 589, in request
    resp = self.send(prep, **send_kwargs)
           ^^^^^^^^^^^^^^^^^^^^^^^^^^^^^^
  File "C:\Users\Andi\AppData\Local\Programs\Python\Python312\Lib\site-packages\requests\sessions.py", line 703, in send
    r = adapter.send(request, **kwargs)
        ^^^^^^^^^^^^^^^^^^^^^^^^^^^^^^^
  File "C:\Users\Andi\AppData\Local\Programs\Python\Python312\Lib\site-packages\requests\adapters.py", line 507, in send
    raise ConnectTimeout(e, request=request)
requests.exceptions.ConnectTimeout: HTTPSConnectionPool(host='your-api-endpoint-here.com', port=443): Max retries exceeded with url: /data (Caused by ConnectTimeoutError(<urllib3.connection.HTTPSConnection object at 0x000001BDF6B9B6E0>, 'Connection to your-api-endpoint-here.com timed out. (connect timeout=None)'))

An error occurred: HTTPSConnectionPool(host='your-api-endpoint-here.com', port=443): Max retries exceeded with url: /data (Caused by ConnectTimeoutError(<urllib3.connection.HTTPSConnection object at 0x000001807F3ABA10>, 'Connection to your-api-endpoint-here.com timed out. (connect timeout=None)'))
Traceback: Traceback (most recent call last):
  File "C:\Users\Andi\AppData\Local\Programs\Python\Python312\Lib\site-packages\urllib3\connection.py", line 203, in _new_conn
    sock = connection.create_connection(
           ^^^^^^^^^^^^^^^^^^^^^^^^^^^^^
  File "C:\Users\Andi\AppData\Local\Programs\Python\Python312\Lib\site-packages\urllib3\util\connection.py", line 85, in create_connection
    raise err
  File "C:\Users\Andi\AppData\Local\Programs\Python\Python312\Lib\site-packages\urllib3\util\connection.py", line 73, in create_connection
    sock.connect(sa)
TimeoutError: [WinError 10060] A connection attempt failed because the connected party did not properly respond after a period of time, or established connection failed because connected host has failed to respond

The above exception was the direct cause of the following exception:

Traceback (most recent call last):
  File "C:\Users\Andi\AppData\Local\Programs\Python\Python312\Lib\site-packages\urllib3\connectionpool.py", line 790, in urlopen
    response = self._make_request(
               ^^^^^^^^^^^^^^^^^^^
  File "C:\Users\Andi\AppData\Local\Programs\Python\Python312\Lib\site-packages\urllib3\connectionpool.py", line 491, in _make_request
    raise new_e
  File "C:\Users\Andi\AppData\Local\Programs\Python\Python312\Lib\site-packages\urllib3\connectionpool.py", line 467, in _make_request
    self._validate_conn(conn)
  File "C:\Users\Andi\AppData\Local\Programs\Python\Python312\Lib\site-packages\urllib3\connectionpool.py", line 1096, in _validate_conn
    conn.connect()
  File "C:\Users\Andi\AppData\Local\Programs\Python\Python312\Lib\site-packages\urllib3\connection.py", line 611, in connect
    self.sock = sock = self._new_conn()
                       ^^^^^^^^^^^^^^^^
  File "C:\Users\Andi\AppData\Local\Programs\Python\Python312\Lib\site-packages\urllib3\connection.py", line 212, in _new_conn
    raise ConnectTimeoutError(
urllib3.exceptions.ConnectTimeoutError: (<urllib3.connection.HTTPSConnection object at 0x000001807F3ABA10>, 'Connection to your-api-endpoint-here.com timed out. (connect timeout=None)')

The above exception was the direct cause of the following exception:

Traceback (most recent call last):
  File "C:\Users\Andi\AppData\Local\Programs\Python\Python312\Lib\site-packages\requests\adapters.py", line 486, in send
    resp = conn.urlopen(
           ^^^^^^^^^^^^^
  File "C:\Users\Andi\AppData\Local\Programs\Python\Python312\Lib\site-packages\urllib3\connectionpool.py", line 844, in urlopen
    retries = retries.increment(
              ^^^^^^^^^^^^^^^^^^
  File "C:\Users\Andi\AppData\Local\Programs\Python\Python312\Lib\site-packages\urllib3\util\retry.py", line 515, in increment
    raise MaxRetryError(_pool, url, reason) from reason  # type: ignore[arg-type]
    ^^^^^^^^^^^^^^^^^^^^^^^^^^^^^^^^^^^^^^^^^^^^^^^^^^^
urllib3.exceptions.MaxRetryError: HTTPSConnectionPool(host='your-api-endpoint-here.com', port=443): Max retries exceeded with url: /data (Caused by ConnectTimeoutError(<urllib3.connection.HTTPSConnection object at 0x000001807F3ABA10>, 'Connection to your-api-endpoint-here.com timed out. (connect timeout=None)'))

During handling of the above exception, another exception occurred:

Traceback (most recent call last):
  File "C:\acm-client\main.py", line 39, in <module>
    response = requests.post(api_endpoint, json=payload)
               ^^^^^^^^^^^^^^^^^^^^^^^^^^^^^^^^^^^^^^^^^
  File "C:\Users\Andi\AppData\Local\Programs\Python\Python312\Lib\site-packages\requests\api.py", line 115, in post
    return request("post", url, data=data, json=json, **kwargs)
           ^^^^^^^^^^^^^^^^^^^^^^^^^^^^^^^^^^^^^^^^^^^^^^^^^^^^
  File "C:\Users\Andi\AppData\Local\Programs\Python\Python312\Lib\site-packages\requests\api.py", line 59, in request
    return session.request(method=method, url=url, **kwargs)
           ^^^^^^^^^^^^^^^^^^^^^^^^^^^^^^^^^^^^^^^^^^^^^^^^^
  File "C:\Users\Andi\AppData\Local\Programs\Python\Python312\Lib\site-packages\requests\sessions.py", line 589, in request
    resp = self.send(prep, **send_kwargs)
           ^^^^^^^^^^^^^^^^^^^^^^^^^^^^^^
  File "C:\Users\Andi\AppData\Local\Programs\Python\Python312\Lib\site-packages\requests\sessions.py", line 703, in send
    r = adapter.send(request, **kwargs)
        ^^^^^^^^^^^^^^^^^^^^^^^^^^^^^^^
  File "C:\Users\Andi\AppData\Local\Programs\Python\Python312\Lib\site-packages\requests\adapters.py", line 507, in send
    raise ConnectTimeout(e, request=request)
requests.exceptions.ConnectTimeout: HTTPSConnectionPool(host='your-api-endpoint-here.com', port=443): Max retries exceeded with url: /data (Caused by ConnectTimeoutError(<urllib3.connection.HTTPSConnection object at 0x000001807F3ABA10>, 'Connection to your-api-endpoint-here.com timed out. (connect timeout=None)'))

An error occurred: HTTPSConnectionPool(host='your-api-endpoint-here.com', port=443): Max retries exceeded with url: /data (Caused by ConnectTimeoutError(<urllib3.connection.HTTPSConnection object at 0x000001807FC80530>, 'Connection to your-api-endpoint-here.com timed out. (connect timeout=None)'))
Traceback: Traceback (most recent call last):
  File "C:\Users\Andi\AppData\Local\Programs\Python\Python312\Lib\site-packages\urllib3\connection.py", line 203, in _new_conn
    sock = connection.create_connection(
           ^^^^^^^^^^^^^^^^^^^^^^^^^^^^^
  File "C:\Users\Andi\AppData\Local\Programs\Python\Python312\Lib\site-packages\urllib3\util\connection.py", line 85, in create_connection
    raise err
  File "C:\Users\Andi\AppData\Local\Programs\Python\Python312\Lib\site-packages\urllib3\util\connection.py", line 73, in create_connection
    sock.connect(sa)
TimeoutError: [WinError 10060] A connection attempt failed because the connected party did not properly respond after a period of time, or established connection failed because connected host has failed to respond

The above exception was the direct cause of the following exception:

Traceback (most recent call last):
  File "C:\Users\Andi\AppData\Local\Programs\Python\Python312\Lib\site-packages\urllib3\connectionpool.py", line 790, in urlopen
    response = self._make_request(
               ^^^^^^^^^^^^^^^^^^^
  File "C:\Users\Andi\AppData\Local\Programs\Python\Python312\Lib\site-packages\urllib3\connectionpool.py", line 491, in _make_request
    raise new_e
  File "C:\Users\Andi\AppData\Local\Programs\Python\Python312\Lib\site-packages\urllib3\connectionpool.py", line 467, in _make_request
    self._validate_conn(conn)
  File "C:\Users\Andi\AppData\Local\Programs\Python\Python312\Lib\site-packages\urllib3\connectionpool.py", line 1096, in _validate_conn
    conn.connect()
  File "C:\Users\Andi\AppData\Local\Programs\Python\Python312\Lib\site-packages\urllib3\connection.py", line 611, in connect
    self.sock = sock = self._new_conn()
                       ^^^^^^^^^^^^^^^^
  File "C:\Users\Andi\AppData\Local\Programs\Python\Python312\Lib\site-packages\urllib3\connection.py", line 212, in _new_conn
    raise ConnectTimeoutError(
urllib3.exceptions.ConnectTimeoutError: (<urllib3.connection.HTTPSConnection object at 0x000001807FC80530>, 'Connection to your-api-endpoint-here.com timed out. (connect timeout=None)')

The above exception was the direct cause of the following exception:

Traceback (most recent call last):
  File "C:\Users\Andi\AppData\Local\Programs\Python\Python312\Lib\site-packages\requests\adapters.py", line 486, in send
    resp = conn.urlopen(
           ^^^^^^^^^^^^^
  File "C:\Users\Andi\AppData\Local\Programs\Python\Python312\Lib\site-packages\urllib3\connectionpool.py", line 844, in urlopen
    retries = retries.increment(
              ^^^^^^^^^^^^^^^^^^
  File "C:\Users\Andi\AppData\Local\Programs\Python\Python312\Lib\site-packages\urllib3\util\retry.py", line 515, in increment
    raise MaxRetryError(_pool, url, reason) from reason  # type: ignore[arg-type]
    ^^^^^^^^^^^^^^^^^^^^^^^^^^^^^^^^^^^^^^^^^^^^^^^^^^^
urllib3.exceptions.MaxRetryError: HTTPSConnectionPool(host='your-api-endpoint-here.com', port=443): Max retries exceeded with url: /data (Caused by ConnectTimeoutError(<urllib3.connection.HTTPSConnection object at 0x000001807FC80530>, 'Connection to your-api-endpoint-here.com timed out. (connect timeout=None)'))

During handling of the above exception, another exception occurred:

Traceback (most recent call last):
  File "C:\acm-client\main.py", line 39, in <module>
    response = requests.post(api_endpoint, json=payload)
               ^^^^^^^^^^^^^^^^^^^^^^^^^^^^^^^^^^^^^^^^^
  File "C:\Users\Andi\AppData\Local\Programs\Python\Python312\Lib\site-packages\requests\api.py", line 115, in post
    return request("post", url, data=data, json=json, **kwargs)
           ^^^^^^^^^^^^^^^^^^^^^^^^^^^^^^^^^^^^^^^^^^^^^^^^^^^^
  File "C:\Users\Andi\AppData\Local\Programs\Python\Python312\Lib\site-packages\requests\api.py", line 59, in request
    return session.request(method=method, url=url, **kwargs)
           ^^^^^^^^^^^^^^^^^^^^^^^^^^^^^^^^^^^^^^^^^^^^^^^^^
  File "C:\Users\Andi\AppData\Local\Programs\Python\Python312\Lib\site-packages\requests\sessions.py", line 589, in request
    resp = self.send(prep, **send_kwargs)
           ^^^^^^^^^^^^^^^^^^^^^^^^^^^^^^
  File "C:\Users\Andi\AppData\Local\Programs\Python\Python312\Lib\site-packages\requests\sessions.py", line 703, in send
    r = adapter.send(request, **kwargs)
        ^^^^^^^^^^^^^^^^^^^^^^^^^^^^^^^
  File "C:\Users\Andi\AppData\Local\Programs\Python\Python312\Lib\site-packages\requests\adapters.py", line 507, in send
    raise ConnectTimeout(e, request=request)
requests.exceptions.ConnectTimeout: HTTPSConnectionPool(host='your-api-endpoint-here.com', port=443): Max retries exceeded with url: /data (Caused by ConnectTimeoutError(<urllib3.connection.HTTPSConnection object at 0x000001807FC80530>, 'Connection to your-api-endpoint-here.com timed out. (connect timeout=None)'))

